<?xml version="1.0"?>
<robot xmlns:xacro="http://www.ros.org/wiki/xacro"  name="robot">
    <!-- CHASSIS LINK -->

    <joint name="chassis_joint" type="fixed">
        <parent link="base_link"/>
        <child link="chassis"/>
        <origin xyz="0 0 0"/>
    </joint>

    <link name="chassis">
        <visual>
            <origin xyz="0 0 0.060225"/>
            <geometry>
                <box size="0.28575 0.2794 0.1016"/>
            </geometry>
            <material name="white"/>
        </visual>
        <collision>
            <origin xyz="0 0 0.075"/>
            <geometry>
                <box size="0.28575 0.2794 0.1016"/>
            </geometry>
        </collision>
        <xacro:inertial_box mass="0.5" x="0.3" y="0.3" z="0.15">
            <origin xyz="0.15 0 0.075" rpy="0 0 0"/>
        </xacro:inertial_box>
    </link>
    <gazebo reference="chassis">
        <material>Gazebo/White</material>
    </gazebo>  

    <joint name="front_caster_base_joint" type="continuous">
        <parent link="base_link"/>
        <child link="front_caster_swivel"/>
        <origin xyz="0.14 0 0.0026" rpy="0 0 0" />
        <axis xyz="0 0 1"/>
    </joint>

    <link name="front_caster_swivel">
        <visual>
            <geometry>
                <cylinder radius="0.05" length="0.04"/>
            </geometry>
            <material name="white"/>
        </visual>
        <collision>
            <geometry>
                <cylinder radius="0.05" length="0.04"/>
            </geometry>
        </collision>
        <xacro:inertial_cylinder mass="0.1" length="0.04" radius="0.05">
            <origin xyz="0 0 0" rpy="0 0 0"/>
        </xacro:inertial_cylinder>
    </link>
    <joint name="front_caster_wheel_joint" type="continuous">
        <parent link="front_caster_swivel"/>
        <child link="front_caster_wheel"/>
        <origin xyz="0 0 0" rpy="1.57075 0 0" />
        <axis xyz="0 0 -1"/>
    </joint>

    <link name="front_caster_wheel">
        <visual>
            <geometry>
                <cylinder radius="0.05" length="0.04"/>
            </geometry>
            <material name="white"/>
        </visual>
        <collision>
            <geometry>
                <cylinder radius="0.05" length="0.04"/>
            </geometry>
        </collision>
        <xacro:inertial_cylinder mass="0.1" length="0.04" radius="0.05">
            <origin xyz="0 0 0" rpy="0 0 0"/>
        </xacro:inertial_cylinder>
    </link>
</robot>