<?xml version="1.0"?>
<robot xmlns:xacro="http://www.ros.org/wiki/xacro" name="robot" >
    <xacro:include filename="gazebo_control.xacro" /> 
    <xacro:include filename="inertial_macros.xacro"/>
    <xacro:include filename="lidar.xacro"/>
    <xacro:include filename="camera.xacro"/>
  <!--  <xacro:include filename="body.xacro"/> -->
    <xacro:arg name="use_ros2_control" default="false"/>
    <xacro:arg name="sim_mode" default="true"/>

    <material name="white">
        <color rgba="1 1 1 1" />
    </material>

    <material name="orange">
        <color rgba="1 0.3 0.1 1"/>
    </material>

    <material name="blue">
        <color rgba="0.2 0.2 1 1"/>
    </material>

    <material name="black">
        <color rgba="0 0 0 1"/>
    </material>

    <material name="red">
        <color rgba="1 0 0 1"/>
    </material>
    <!-- BASE LINK -->

    <link name="base_link">

    </link>

    <!-- CHASSIS LINK -->

    <joint name="chassis_joint" type="fixed">
        <parent link="base_link"/>
        <child link="chassis"/>
        <origin xyz="0 0 0"/>
    </joint>

    <link name="chassis">
        <visual>
            <origin xyz="0 0 0.060225"/>
            <geometry>
                <box size="0.28575 0.2794 0.1016"/>
            </geometry>
            <material name="white"/>
        </visual>
        <collision>
            <origin xyz="0 0 0.075"/>
            <geometry>
                <box size="0.28575 0.2794 0.1016"/>
            </geometry>
        </collision>
        <xacro:inertial_box mass="0.5" x="0.3" y="0.3" z="0.15">
            <origin xyz="0.15 0 0.075" rpy="0 0 0"/>
        </xacro:inertial_box>
    </link>
    <gazebo reference="chassis">
        <material>Gazebo/White</material>
    </gazebo>  

    <!-- BODY BASE LINK -->

    <joint name="body_base_joint" type="fixed">
        <parent link="chassis"/>
        <child link="body_base"/>
        <origin xyz="0 0 0"/>
    </joint>

    <link name="body_base">
        <visual>
            <origin xyz="0 0 0.04"/>
            <geometry>
                <cylinder radius="0.2286" length="0.1524"/>
            </geometry>
            <material name="black"/>
        </visual>
        <collision>
            <origin xyz="0 0 0.060225"/>
            <geometry>
                <cylinder radius="0.2286" length="0.1524"/>
            </geometry>
        </collision>
        <xacro:inertial_cylinder mass="0.1" length="0.1524" radius="0.2286">
            <origin xyz="0 0 0" rpy="0 0 0"/>
        </xacro:inertial_cylinder>
    </link>
    <gazebo reference="body_base">
        <material>Gazebo/Black</material>
    </gazebo> 

    <!-- BODY LINK -->

    <joint name="body_joint" type="fixed">
        <parent link="chassis"/>
        <child link="body"/>
        <origin xyz="0 0 0.1905"/>
    </joint>

    <link name="body">
        <visual>
            <origin xyz="0 0 0.1905"/>
            <geometry>
                <cylinder radius="0.1524" length="0.7493"/>
            </geometry>
            <material name="white"/>
        </visual>
        <collision>
            <origin xyz="0 0 0.1905"/>
            <geometry>
                <cylinder radius="0.1524" length="0.7493"/>
            </geometry>
        </collision>
        <xacro:inertial_cylinder mass="0.35" length="0.7493" radius="0.1524">
            <origin xyz="0 0 0" rpy="0 0 0"/>
        </xacro:inertial_cylinder>
    </link>
    <gazebo reference="chassis">
        <material>Gazebo/White</material>
    </gazebo>

    <!-- LEFT WHEEL LINK -->

    <joint name="left_wheel_joint" type="continuous">
        <parent link="base_link"/>
        <child link="left_wheel"/>
        <origin xyz="0 0.175 0" rpy="-1.57075 0 0" />
        <axis xyz="0 0 1"/>
    </joint>

    <link name="left_wheel">
        <visual>
            <geometry>
                <cylinder radius="0.05" length="0.04"/>
            </geometry>
            <material name="blue"/>
        </visual>
        <collision>
            <geometry>
                <cylinder radius="0.05" length="0.04"/>
            </geometry>
        </collision>
        <xacro:inertial_cylinder mass="0.1" length="0.04" radius="0.05">
            <origin xyz="0 0 0" rpy="0 0 0"/>
        </xacro:inertial_cylinder>
    </link>
    <gazebo reference="left_wheel">
        <material>Gazebo/Blue</material>
    </gazebo>

    <!-- RIGHT WHEEL LINK -->

    <joint name="right_wheel_joint" type="continuous">
        <parent link="base_link"/>
        <child link="right_wheel"/>
        <origin xyz="0 -0.175 0" rpy="1.57075 0 0" />
        <axis xyz="0 0 -1"/>
    </joint>

    <link name="right_wheel">
        <visual>
            <geometry>
                <cylinder radius="0.05" length="0.04"/>
            </geometry>
            <material name="blue"/>
        </visual>
        <collision>
            <geometry>
                <cylinder radius="0.05" length="0.04"/>
            </geometry>
        </collision>
        <xacro:inertial_cylinder mass="0.1" length="0.04" radius="0.05">
            <origin xyz="0 0 0" rpy="0 0 0"/>
        </xacro:inertial_cylinder>
    </link>
    <gazebo reference="right_wheel">
        <material>Gazebo/blue</material>
    </gazebo>

    <!-- FRONT CASTER WHEEL LINK -->

    <joint name="front_caster_base_joint" type="continuous">
        <parent link="base_link"/>
        <child link="front_caster_swivel"/>
        <origin xyz="0.14 0 0.0026" rpy="0 0 0" />
        <axis xyz="0 0 1"/>
    </joint>

    <link name="front_caster_swivel">
        <visual>
            <geometry>
                <cylinder radius="0.05" length="0.04"/>
            </geometry>
            <material name="white"/>
        </visual>
        <collision>
            <geometry>
                <cylinder radius="0.05" length="0.04"/>
            </geometry>
        </collision>
        <xacro:inertial_cylinder mass="0.1" length="0.04" radius="0.05">
            <origin xyz="0 0 0" rpy="0 0 0"/>
        </xacro:inertial_cylinder>
    </link>
    <joint name="front_caster_wheel_joint" type="continuous">
        <parent link="front_caster_swivel"/>
        <child link="front_caster_wheel"/>
        <origin xyz="0 0 0" rpy="1.57075 0 0" />
        <axis xyz="0 0 -1"/>
    </joint>

    <link name="front_caster_wheel">
        <visual>
            <geometry>
                <cylinder radius="0.05" length="0.04"/>
            </geometry>
            <material name="white"/>
        </visual>
        <collision>
            <geometry>
                <cylinder radius="0.05" length="0.04"/>
            </geometry>
        </collision>
        <xacro:inertial_cylinder mass="0.1" length="0.04" radius="0.05">
            <origin xyz="0 0 0" rpy="0 0 0"/>
        </xacro:inertial_cylinder>
    </link>
    <gazebo reference="front_caster_wheel">
        <material>Gazebo/Blue</material>
        <mu1 value="0.001"/>
        <mu2 value="0.001"/>
    </gazebo>   

    <!-- REAR CASTER WHEEL LINK -->

    <joint name="rear_caster_base_joint" type="continuous">
        <parent link="base_link"/>
        <child link="rear_caster_swivel"/>
        <origin xyz="-0.142875 0 0.0026" rpy="0 0 0" />
        <axis xyz="0 0 1"/>
    </joint>

    <link name="rear_caster_swivel">
        <visual>
            <geometry>
                <cylinder radius="0.05" length="0.04"/>
            </geometry>
            <material name="white"/>
        </visual>
        <collision>
            <geometry>
                <cylinder radius="0.05" length="0.04"/>
            </geometry>
        </collision>
        <xacro:inertial_cylinder mass="0.1" length="0.04" radius="0.05">
            <origin xyz="0 0 0" rpy="0 0 0"/>
        </xacro:inertial_cylinder>
    </link>
    <joint name="rear_caster_wheel_joint" type="continuous">
        <parent link="rear_caster_swivel"/>
        <child link="rear_caster_wheel"/>
        <origin xyz="0 0 0" rpy="1.57075 0 0" />
        <axis xyz="0 0 -1"/>
    </joint>

    <link name="rear_caster_wheel">
        <visual>
            <geometry>
                <cylinder radius="0.05" length="0.04"/>
            </geometry>
            <material name="white"/>
        </visual>
        <collision>
            <geometry>
                <cylinder radius="0.05" length="0.04"/>
            </geometry>
        </collision>
        <xacro:inertial_cylinder mass="0.1" length="0.04" radius="0.05">
            <origin xyz="0 0 0" rpy="0 0 0"/>
        </xacro:inertial_cylinder>
    </link>
    <gazebo reference="caster_wheel">
        <material>Gazebo/Blue</material>
        <mu1 value="0.001"/>
        <mu2 value="0.001"/>
    </gazebo>

    <!-- TOP SONAR --> 

    <!--SONAR 1--> 
    <joint name="sonar_front_1_joint" type="fixed">
        <axis xyz="0 1 0" />
        <origin rpy="0 0 0" xyz="0.15 0 0.671" />
        <parent link="chassis"/>
        <child link="sonar_top_1"/>
    </joint>
    <link name="sonar_top_1">
        <collision>
        <origin xyz="0 0 0" rpy="0 0 0"/>
        <geometry>
            <box size="0.01 0.01 0.01"/>
        </geometry>
        </collision>
        <visual>
        <origin xyz="0 0 0" rpy="0 0 0"/>
        <geometry>
            <box size="0.01 0.01 0.01"/>
        </geometry>
        </visual>
        <inertial>
        <mass value="1e-5" />
        <origin xyz="0 0 0" rpy="0 0 0"/>
        <inertia ixx="1e-6" ixy="0" ixz="0" iyy="1e-6" iyz="0" izz="1e-6" />
        </inertial>
    </link>
    <gazebo reference="sonar_top_1">        
    <sensor type="ray" name="TeraRanger">
        <pose>0 0 0 0 0 0</pose>
        <visualize>true</visualize>
        <update_rate>50</update_rate>
        <ray>
            <scan>
                <horizontal>
                <samples>10</samples>
                <resolution>1</resolution> 
                <min_angle>-0.14835</min_angle>
                <max_angle>0.14835</max_angle>
                </horizontal>
                <vertical>
                <samples>10</samples>
                <resolution>1</resolution> 
                <min_angle>-0.14835</min_angle>
                <max_angle>0.14835</max_angle> 
                </vertical>
            </scan>
            <range>
                <min>0.01</min>
                <max>2</max>
                <resolution>0.02</resolution>
            </range>
        </ray>
        <plugin filename="libgazebo_ros_range.so" name="gazebo_ros_range">
            <gaussianNoise>0.005</gaussianNoise>
            <alwaysOn>true</alwaysOn>
            <updateRate>50</updateRate>
            <topicName>sensor/Range</topicName>
            <frameName>sonar_top_1</frameName>
            <radiation>INFRARED</radiation>
            <fov>0.2967</fov>
        </plugin>
    </sensor>  
    </gazebo>
     <!--SONAR 2--> 
    <joint name="sonar_front_2_joint" type="fixed">
        <axis xyz="0 1 0" />
        <origin rpy="0 0 0" xyz="0.15 0 0.5948" />
        <parent link="chassis"/>
        <child link="sonar_top_2"/>
    </joint>
    <link name="sonar_top_2">
        <collision>
        <origin xyz="0 0 0" rpy="0 0 0"/>
        <geometry>
            <box size="0.01 0.01 0.01"/>
        </geometry>
        </collision>
        <visual>
        <origin xyz="0 0 0" rpy="0 0 0"/>
        <geometry>
            <box size="0.01 0.01 0.01"/>
        </geometry>
        </visual>
        <inertial>
        <mass value="1e-5" />
        <origin xyz="0 0 0" rpy="0 0 0"/>
        <inertia ixx="1e-6" ixy="0" ixz="0" iyy="1e-6" iyz="0" izz="1e-6" />
        </inertial>
    </link>
    <gazebo reference="sonar_top_2">        
        <sensor type="ray" name="TeraRanger">
            <pose>0 0 0 0 0 0</pose>
            <visualize>true</visualize>
            <update_rate>50</update_rate>
            <ray>
                <scan>
                    <horizontal>
                    <samples>10</samples>
                    <resolution>1</resolution> 
                    <min_angle>-0.14835</min_angle>
                    <max_angle>0.14835</max_angle>
                    </horizontal>
                    <vertical>
                    <samples>10</samples>
                    <resolution>1</resolution> 
                    <min_angle>-0.14835</min_angle>
                    <max_angle>0.14835</max_angle> 
                    </vertical>
                </scan>
                <range>
                    <min>0.01</min>
                    <max>2</max>
                    <resolution>0.02</resolution>
                </range>
            </ray>
            <plugin filename="libgazebo_ros_range.so" name="ultrasonic_sensor_2">
                <gaussianNoise>0.005</gaussianNoise>
                <alwaysOn>true</alwaysOn>
                <updateRate>50</updateRate>
                <topicName>sensor_msgs/range_2</topicName>
                <frameName>sonar_top_2</frameName>
                <radiation>ultrasound</radiation>
                <fov>0.2967</fov>
            </plugin>
        </sensor>  
    </gazebo>

     <!--SONAR 3--> 
    <joint name="sonar_front_3_joint" type="fixed">
        <axis xyz="0 1 0" />
        <origin rpy="0 0 0" xyz="0.15 0 0.5186" />
        <parent link="chassis"/>
        <child link="sonar_top_3"/>
    </joint>
    <link name="sonar_top_3">
        <collision>
        <origin xyz="0 0 0" rpy="0 0 0"/>
        <geometry>
            <box size="0.01 0.01 0.01"/>
        </geometry>
        </collision>
        <visual>
        <origin xyz="0 0 0" rpy="0 0 0"/>
        <geometry>
            <box size="0.01 0.01 0.01"/>
        </geometry>
        </visual>
        <inertial>
        <mass value="1e-5" />
        <origin xyz="0 0 0" rpy="0 0 0"/>
        <inertia ixx="1e-6" ixy="0" ixz="0" iyy="1e-6" iyz="0" izz="1e-6" />
        </inertial>
    </link>
    <gazebo reference="sonar_top_3">        
        <sensor type="ray" name="TeraRanger">
            <pose>0 0 0 0 0 0</pose>
            <visualize>true</visualize>
            <update_rate>50</update_rate>
            <ray>
                <scan>
                    <horizontal>
                    <samples>10</samples>
                    <resolution>1</resolution> 
                    <min_angle>-0.14835</min_angle>
                    <max_angle>0.14835</max_angle>
                    </horizontal>
                    <vertical>
                    <samples>10</samples>
                    <resolution>1</resolution> 
                    <min_angle>-0.14835</min_angle>
                    <max_angle>0.14835</max_angle> 
                    </vertical>
                </scan>
                <range>
                    <min>0.01</min>
                    <max>2</max>
                    <resolution>0.02</resolution>
                </range>
            </ray>
            <plugin filename="libgazebo_ros_range.so" name="ultrasonic_sensor_3">
                <gaussianNoise>0.005</gaussianNoise>
                <alwaysOn>true</alwaysOn>
                <updateRate>50</updateRate>
                <topicName>sensor_msgs/range_3</topicName>
                <frameName>sonar_top</frameName>
                <radiation>ultrasound</radiation>
                <fov>0.2967</fov>
            </plugin>
        </sensor>  
    </gazebo>

     <!--SONAR 4--> 
    <joint name="sonar_front_4_joint" type="fixed">
        <axis xyz="0 1 0" />
        <origin rpy="0 0 0" xyz="0.15 0 0.4424" />
        <parent link="chassis"/>
        <child link="sonar_top_4"/>
    </joint>
    <link name="sonar_top_4">
        <collision>
        <origin xyz="0 0 0" rpy="0 0 0"/>
        <geometry>
            <box size="0.01 0.01 0.01"/>
        </geometry>
        </collision>
        <visual>
        <origin xyz="0 0 0" rpy="0 0 0"/>
        <geometry>
            <box size="0.01 0.01 0.01"/>
        </geometry>
        </visual>
        <inertial>
        <mass value="1e-5" />
        <origin xyz="0 0 0" rpy="0 0 0"/>
        <inertia ixx="1e-6" ixy="0" ixz="0" iyy="1e-6" iyz="0" izz="1e-6" />
        </inertial>
    </link>
    <gazebo reference="sonar_top_4">        
        <sensor type="ray" name="TeraRanger">
            <pose>0 0 0 0 0 0</pose>
            <visualize>true</visualize>
            <update_rate>50</update_rate>
            <ray>
                <scan>
                    <horizontal>
                    <samples>10</samples>
                    <resolution>1</resolution> 
                    <min_angle>-0.14835</min_angle>
                    <max_angle>0.14835</max_angle>
                    </horizontal>
                    <vertical>
                    <samples>10</samples>
                    <resolution>1</resolution> 
                    <min_angle>-0.14835</min_angle>
                    <max_angle>0.14835</max_angle> 
                    </vertical>
                </scan>
                <range>
                    <min>0.01</min>
                    <max>2</max>
                    <resolution>0.02</resolution>
                </range>
            </ray>
            <plugin filename="libgazebo_ros_range.so" name="ultrasonic_sensor_4">
                <gaussianNoise>0.005</gaussianNoise>
                <alwaysOn>true</alwaysOn>
                <updateRate>50</updateRate>
                <topicName>sensor_msgs/range_4</topicName>
                <frameName>sonar_top</frameName>
                <radiation>ultrasound</radiation>
                <fov>0.2967</fov>
            </plugin>
        </sensor>  
    </gazebo>

     <!--SONAR 5--> 
    <joint name="sonar_front_5_joint" type="fixed">
        <axis xyz="0 1 0" />
        <origin rpy="0 0 0" xyz="0.15 0 0.3662" />
        <parent link="chassis"/>
        <child link="sonar_top_5"/>
    </joint>
    <link name="sonar_top_5">
        <collision>
        <origin xyz="0 0 0" rpy="0 0 0"/>
        <geometry>
            <box size="0.01 0.01 0.01"/>
        </geometry>
        </collision>
        <visual>
        <origin xyz="0 0 0" rpy="0 0 0"/>
        <geometry>
            <box size="0.01 0.01 0.01"/>
        </geometry>
        </visual>
        <inertial>
        <mass value="1e-5" />
        <origin xyz="0 0 0" rpy="0 0 0"/>
        <inertia ixx="1e-6" ixy="0" ixz="0" iyy="1e-6" iyz="0" izz="1e-6" />
        </inertial>
    </link>
    <gazebo reference="sonar_top_5">        
        <sensor type="ray" name="TeraRanger">
            <pose>0 0 0 0 0 0</pose>
            <visualize>true</visualize>
            <update_rate>50</update_rate>
            <ray>
                <scan>
                    <horizontal>
                    <samples>10</samples>
                    <resolution>1</resolution> 
                    <min_angle>-0.14835</min_angle>
                    <max_angle>0.14835</max_angle>
                    </horizontal>
                    <vertical>
                    <samples>10</samples>
                    <resolution>1</resolution> 
                    <min_angle>-0.14835</min_angle>
                    <max_angle>0.14835</max_angle> 
                    </vertical>
                </scan>
                <range>
                    <min>0.01</min>
                    <max>2</max>
                    <resolution>0.02</resolution>
                </range>
            </ray>
            <plugin filename="libgazebo_ros_range.so" name="ultrasonic_sensor_5">
                <gaussianNoise>0.005</gaussianNoise>
                <alwaysOn>true</alwaysOn>
                <updateRate>50</updateRate>
                <topicName>sensor_msgs/range_5</topicName>
                <frameName>sonar_top</frameName>
                <radiation>ultrasound</radiation>
                <fov>0.2967</fov>
            </plugin>
        </sensor>  
    </gazebo>

     <!--SONAR 6--> 
    <joint name="sonar_front_6_joint" type="fixed">
        <axis xyz="0 1 0" />
        <origin rpy="0 0 0" xyz="0.15 0 0.29" />
        <parent link="chassis"/>
        <child link="sonar_top_6"/>
    </joint>
    <link name="sonar_top_6">
        <collision>
        <origin xyz="0.15 0 0.29" rpy="0 0 0"/>
        <geometry>
            <box size="0.01 0.01 0.01"/>
        </geometry>
        </collision>
        <visual>
        <origin xyz="0 0 0" rpy="0 0 0"/>
        <geometry>
            <box size="0.01 0.01 0.01"/>
        </geometry>
        </visual>
        <inertial>
        <mass value="1e-5" />
        <origin xyz="0 0 0" rpy="0 0 0"/>
        <inertia ixx="1e-6" ixy="0" ixz="0" iyy="1e-6" iyz="0" izz="1e-6" />
        </inertial>
    </link>
    <gazebo reference="sonar_top_6">        
        <sensor type="ray" name="TeraRanger">
            <pose>0 0 0 0 0 0</pose>
            <visualize>true</visualize>
            <update_rate>50</update_rate>
            <ray>
                <scan>
                    <horizontal>
                    <samples>10</samples>
                    <resolution>1</resolution> 
                    <min_angle>-0.14835</min_angle>
                    <max_angle>0.14835</max_angle>
                    </horizontal>
                    <vertical>
                    <samples>10</samples>
                    <resolution>1</resolution> 
                    <min_angle>-0.14835</min_angle>
                    <max_angle>0.14835</max_angle> 
                    </vertical>
                </scan>
                <range>
                    <min>0.01</min>
                    <max>2</max>
                    <resolution>0.02</resolution>
                </range>
            </ray>
            <plugin filename="libgazebo_ros_range.so" name="ultrasonic_sensor_6">
                <gaussianNoise>0.005</gaussianNoise>
                <alwaysOn>true</alwaysOn>
                <updateRate>50</updateRate>
                <topicName>sensor_msgs/range_6</topicName>
                <frameName>sonar_top</frameName>
                <radiation>ultrasound</radiation>
                <fov>0.2967</fov>
            </plugin>
        </sensor>  
    </gazebo>

     <!--SONAR BASE FRONT--> 
    <joint name="sonar_front_joint" type="fixed">
        <axis xyz="0 1 0" />
        <origin rpy="0 0 0" xyz="0.2259 0 0.0438" />
        <parent link="chassis"/>
        <child link="sonar_front"/>
    </joint>
    <link name="sonar_front">
        <collision>
        <origin xyz="0.001975 0 0.0038" rpy="0 0 0"/>
        <geometry>
            <box size="0.01 0.01 0.01"/>
        </geometry>
        </collision>
        <visual>
        <origin xyz="0 0 0" rpy="0 0 0"/>
        <geometry>
            <box size="0.01 0.01 0.01"/>
        </geometry>
        </visual>
        <inertial>
        <mass value="1e-5" />
        <origin xyz="0 0 0" rpy="0 0 0"/>
        <inertia ixx="1e-6" ixy="0" ixz="0" iyy="1e-6" iyz="0" izz="1e-6" />
        </inertial>
    </link>
    <gazebo reference="sonar_front">        
        <sensor type="ray" name="TeraRanger">
            <pose>0 0 0 0 0 0</pose>
            <visualize>true</visualize>
            <update_rate>50</update_rate>
            <ray>
                <scan>
                    <horizontal>
                    <samples>10</samples>
                    <resolution>1</resolution> 
                    <min_angle>-0.14835</min_angle>
                    <max_angle>0.14835</max_angle>
                    </horizontal>
                    <vertical>
                    <samples>10</samples>
                    <resolution>1</resolution> 
                    <min_angle>-0.14835</min_angle>
                    <max_angle>0.14835</max_angle> 
                    </vertical>
                </scan>
                <range>
                    <min>0.01</min>
                    <max>2</max>
                    <resolution>0.02</resolution>
                </range>
            </ray>
            <plugin filename="libgazebo_ros_range.so" name="ultrasonic_sensor_7">
                <gaussianNoise>0.005</gaussianNoise>
                <alwaysOn>true</alwaysOn>
                <updateRate>50</updateRate>
                <topicName>sensor_msgs/range_front</topicName>
                <frameName>sonar_base</frameName>
                <radiation>ultrasound</radiation>
                <fov>0.2967</fov>
            </plugin>
        </sensor>  
    </gazebo>

<!-- LEFT SONAR --> 
    <joint name="sonar_left_joint" type="fixed">
        <axis xyz="0 1 0" />
        <origin rpy="0 0 1.57" xyz="0 0.2259 0.0438" />
        <parent link="chassis"/>
        <child link="base_sonar_left"/>
    </joint>
    <link name="base_sonar_left">
        <collision>
        <origin xyz="0 0 0" rpy="0 0 0"/>
        <geometry>
            <box size="0.01 0.01 0.01"/>
        </geometry>
        </collision>
        <visual>
        <origin xyz="0 0 0" rpy="0 0 0"/>
        <geometry>
            <box size="0.01 0.01 0.01"/>
        </geometry>
        </visual>
        <inertial>
        <mass value="1e-5" />
        <origin xyz="0 0 0" rpy="0 0 0"/>
        <inertia ixx="1e-6" ixy="0" ixz="0" iyy="1e-6" iyz="0" izz="1e-6" />
        </inertial>
    </link>
    <gazebo reference="base_sonar_left">        
        <sensor type="ray" name="TeraRanger">
            <pose>0 0 0 0 0 0</pose>
            <visualize>true</visualize>
            <update_rate>50</update_rate>
            <ray>
                <scan>
                    <horizontal>
                    <samples>10</samples>
                    <resolution>1</resolution> 
                    <min_angle>-0.14835</min_angle>
                    <max_angle>0.14835</max_angle>
                    </horizontal>
                    <vertical>
                    <samples>10</samples>
                    <resolution>1</resolution> 
                    <min_angle>-0.14835</min_angle>
                    <max_angle>0.14835</max_angle> 
                    </vertical>
                </scan>
                <range>
                    <min>0.01</min>
                    <max>2</max>
                    <resolution>0.02</resolution>
                </range>
            </ray>
            <plugin filename="libgazebo_ros_range.so" name="ultrasonic_sensor_8">
                <gaussianNoise>0.005</gaussianNoise>
                <alwaysOn>true</alwaysOn>
                <updateRate>50</updateRate>
                <topicName>sensor_msgs/range_left</topicName>
                <frameName>sonar_base</frameName>
                <radiation>ultrasound</radiation>
                <fov>0.2967</fov>
            </plugin>
        </sensor>  
    </gazebo>

<!-- RIGHT SONAR  -->
    <joint name="sonar_right_joint" type="fixed">
        <axis xyz="0 1 0" />
        <origin rpy="0 0 -1.57" xyz="0 -0.2259 0.0438" />
        <parent link="chassis"/>
        <child link="base_sonar_right"/>
    </joint>
    <link name="base_sonar_right">
        <collision>
        <origin xyz="0 0 0" rpy="0 0 0"/>
        <geometry>
            <box size="0.01 0.01 0.01"/>
        </geometry>
        </collision>
        <visual>
        <origin xyz="0 0 0" rpy="0 0 0"/>
        <geometry>
            <box size="0.01 0.01 0.01"/>
        </geometry>
        </visual>
        <inertial>
        <mass value="1e-5" />
        <origin xyz="0 0 0" rpy="0 0 0"/>
        <inertia ixx="1e-6" ixy="0" ixz="0" iyy="1e-6" iyz="0" izz="1e-6" />
        </inertial>
    </link>
    <gazebo reference="base_sonar_right">        
        <sensor type="ray" name="TeraRanger">
            <pose>0 0 0 0 0 0</pose>
            <visualize>true</visualize>
            <update_rate>50</update_rate>
            <ray>
                <scan>
                    <horizontal>
                    <samples>10</samples>
                    <resolution>1</resolution> 
                    <min_angle>-0.14835</min_angle>
                    <max_angle>0.14835</max_angle>
                    </horizontal>
                    <vertical>
                    <samples>10</samples>
                    <resolution>1</resolution> 
                    <min_angle>-0.14835</min_angle>
                    <max_angle>0.14835</max_angle> 
                    </vertical>
                </scan>
                <range>
                    <min>0.01</min>
                    <max>2</max>
                    <resolution>0.02</resolution>
                </range>
            </ray>
            <plugin filename="libgazebo_ros_range.so" name="ultrasonic_sensor_9">
                <gaussianNoise>0.005</gaussianNoise>
                <alwaysOn>true</alwaysOn>
                <updateRate>50</updateRate>
                <topicName>sensor_msgs/range_right</topicName>
                <frameName>sonar_base</frameName>
                <radiation>ultrasound</radiation>
                <fov>0.2967</fov>
            </plugin>
        </sensor>  
    </gazebo>

<!-- REAR SONAR  --> 
    <joint name="sonar_rear_joint" type="fixed">
        <axis xyz="0 1 0" />
        <origin rpy="0 0 -3.14" xyz="-0.227 0 0.0438" />
        <parent link="chassis"/>
        <child link="base_sonar_rear"/>
    </joint>
    <link name="base_sonar_rear">
        <collision>
        <origin xyz="0 0 0" rpy="0 0 0"/>
        <geometry>
            <box size="0.01 0.01 0.01"/>
        </geometry>
        </collision>
        <visual>
        <origin xyz="0 0 0" rpy="0 0 0"/>
        <geometry>
            <box size="0.01 0.01 0.01"/>
        </geometry>
        </visual>
        <inertial>
        <mass value="1e-5" />
        <origin xyz="0 0 0" rpy="0 0 0"/>
        <inertia ixx="1e-6" ixy="0" ixz="0" iyy="1e-6" iyz="0" izz="1e-6" />
        </inertial>
    </link>
    <gazebo reference="base_sonar_rear">        
        <sensor type="ray" name="TeraRanger">
            <pose>0 0 0 0 0 0</pose>
            <visualize>true</visualize>
            <update_rate>50</update_rate>
            <ray>
                <scan>
                    <horizontal>
                    <samples>10</samples>
                    <resolution>1</resolution> 
                    <min_angle>-0.14835</min_angle>
                    <max_angle>0.14835</max_angle>
                    </horizontal>
                    <vertical>
                    <samples>10</samples>
                    <resolution>1</resolution> 
                    <min_angle>-0.14835</min_angle>
                    <max_angle>0.14835</max_angle> 
                    </vertical>
                </scan>
                <range>
                    <min>0.01</min>
                    <max>2</max>
                    <resolution>0.02</resolution>
                </range>
            </ray>
            <plugin filename="libgazebo_ros_range.so" name="ultrasonic_sensor_10">
                <gaussianNoise>0.005</gaussianNoise>
                <alwaysOn>true</alwaysOn>
                <updateRate>50</updateRate>
                <ros>
                    <remapping>~/out:=ultrasonic_sensor_10</remapping>
                </ros>
                <output_type>sensor_msgs/Range</output_type>
                <radiation_type>ultrasound</radiation_type>
                <frame_name>base_sonar_rear</frame_name>
                <fov>0.2967</fov>
            </plugin>
        </sensor>  
    </gazebo>

   
</robot>