<?xml version="1.0"?>
<robot xmlns:xacro="http://www.ros.org/wiki/xacro" name="robot" >
    <xacro:include filename="gazebo_control.xacro" /> 
    <xacro:include filename="inertial_macros.xacro"/>
    <xacro:include filename="lidar.xacro"/>
    <xacro:include filename="camera.xacro"/>
    <xacro:arg name="use_ros2_control" default="false"/>
    <xacro:arg name="sim_mode" default="true"/>
    
    <material name="white">
        <color rgba="1 1 1 1" />
    </material>

    <material name="orange">
        <color rgba="1 0.3 0.1 1"/>
    </material>

    <material name="blue">
        <color rgba="0.2 0.2 1 1"/>
    </material>

    <material name="black">
        <color rgba="0 0 0 1"/>
    </material>

   <!-- BASE LINK -->
    <link name="base_link">

    </link>


    <!-- CHASSIS LINK -->

    <joint name="chassis_joint" type="fixed">
        <parent link="base_link"/>
        <child link="chassis"/>
        <origin xyz="-0.15 0 0.07"/>
    </joint>

    <link name="chassis">
        <visual>
            <origin xyz="0.15 0 0.0635"/>
            <geometry>
                <box size="0.381 0.381 0.15"/>
            </geometry>
            <material name="white"/>
        </visual>
        <collision>
            <origin xyz="0.15 0 0.0635"/>
            <geometry>
                <box size="0.381 0.381 0.15"/>
            </geometry>
        </collision>
        <xacro:inertial_box mass="1" x="0.381" y="0.381" z="0.15">
            <origin xyz="0.15 0 0.0635" rpy="0 0 0"/>
        </xacro:inertial_box>
    </link>
    <gazebo reference="chassis">
        <material>Gazebo/White</material>
    </gazebo>  

    <!-- BODY BASE LINK -->

    <joint name="body_base_joint" type="fixed">
        <parent link="chassis"/>
        <child link="body_base"/>
        <origin xyz="-0.1 0 0.07"/>
    </joint>

    <link name="body_base">
        <visual>
            <origin xyz="0.25 0 0"/>
            <geometry>
                <cylinder radius="0.2921" length="0.1778"/>
            </geometry>
            <material name="white"/>
        </visual>
        <collision>
            <origin xyz="0.25 0 0"/>
            <geometry>
                <cylinder radius="0.2921" length="0.1778"/>
            </geometry>
        </collision>
        <xacro:inertial_cylinder mass="0.2" length="0.1778" radius="0.2921">
            <origin xyz="0 0 0" rpy="0 0 0"/>
        </xacro:inertial_cylinder>
    </link>
    <gazebo reference="chassis">
        <material>Gazebo/White</material>
    </gazebo>  


    <!-- BODY LINK -->

    <joint name="body_joint" type="fixed">
        <parent link="chassis"/>
        <child link="body"/>
        <origin xyz="-0.1 0 0.1"/>
    </joint>

    <link name="body">
        <visual>
            <origin xyz="0.25 0 0.42"/>
            <geometry>
                <cylinder radius="0.2286" length="0.7366"/>
            </geometry>
            <material name="white"/>
        </visual>
        <collision>
            <origin xyz="0.25 0 0.42"/>
            <geometry>
                <cylinder radius="0.2286" length="0.7366"/>
            </geometry>
        </collision>
        <xacro:inertial_cylinder mass="0.35" length="0.7366" radius="0.2286">
            <origin xyz="0 0 0" rpy="0 0 0"/>
        </xacro:inertial_cylinder>
    </link>
    <gazebo reference="chassis">
        <material>Gazebo/White</material>
    </gazebo>

    <!-- LEFT WHEEL LINK -->

    <joint name="left_wheel_joint" type="continuous">
        <parent link="base_link"/>
        <child link="left_wheel"/>
        <origin xyz="0 0.22 0.07" rpy="-1.57075 0 0" />
        <axis xyz="0 0 1"/>
    </joint>

    <link name="left_wheel">
        <visual>
            <geometry>
                <cylinder radius="0.05" length="0.0508"/>
            </geometry>
            <material name="blue"/>
        </visual>
        <collision>
            <geometry>
                <cylinder radius="0.05" length="0.0508"/>
            </geometry>
        </collision>
        <xacro:inertial_cylinder mass="0.3" length="0.0508" radius="0.05">
            <origin xyz="0 0 0" rpy="0 0 0"/>
        </xacro:inertial_cylinder>
    </link>
    <gazebo reference="left_wheel">
        <material>Gazebo/White</material>
    </gazebo>

    <!-- RIGHT WHEEL LINK -->

    <joint name="right_wheel_joint" type="continuous">
        <parent link="base_link"/>
        <child link="right_wheel"/>
        <origin xyz="0 -0.22 0.07" rpy="-1.57075 0 0" />
        <axis xyz="0 0 1"/>
    </joint>

    <link name="right_wheel">
        <visual>
            <geometry>
                <cylinder radius="0.05" length="0.0508"/>
            </geometry>
            <material name="blue"/>
        </visual>
        <collision>
            <geometry>
                <cylinder radius="0.05" length="0.0508"/>
            </geometry>
        </collision>
        <xacro:inertial_cylinder mass="0.3" length="0.0508" radius="0.05">
            <origin xyz="0 0 0" rpy="0 0 0"/>
        </xacro:inertial_cylinder>
    </link>
    <gazebo reference="right_wheel">
        <material>Gazebo/White</material>
    </gazebo>

    <!-- FRONT RIGHT CASTER WHEEL LINK -->

    <joint name="front_right_caster_wheel_joint" type="continuous">
        <parent link="chassis"/>
        <child link="front_right_caster_wheel"/>
        <origin xyz="0.33 -0.1 0"/>
    </joint>

    <link name="front_right_caster_wheel">
        <visual>
            <geometry>
                <sphere radius="0.05"/>
            </geometry>
            <material name="black"/>
        </visual>
        <collision>
            <geometry>
                <sphere radius="0.05"/>
            </geometry>
        </collision>
        <xacro:inertial_sphere mass="0.1" radius="0.05">
            <origin xyz="0 0 0" rpy="0 0 0"/>
        </xacro:inertial_sphere>
    </link>
    <gazebo reference="caster_wheel">
        <material>Gazebo/Black</material>
        <mu1 value="0.001"/>
        <mu2 value="0.001"/>
    </gazebo>

    <!-- FRONT LEFT CASTER WHEEL LINK -->

    <joint name="front_left_caster_wheel_joint" type="continuous">
        <parent link="chassis"/>
        <child link="front_left_caster_wheel"/>
        <origin xyz="0.33 0.1 0"/>
    </joint>

    <link name="front_left_caster_wheel">
        <visual>
            <geometry>
                <sphere radius="0.05"/>
            </geometry>
            <material name="black"/>
        </visual>
        <collision>
            <geometry>
                <sphere radius="0.05"/>
            </geometry>
        </collision>
        <xacro:inertial_sphere mass="0.1" radius="0.05">
            <origin xyz="0 0 0" rpy="0 0 0"/>
        </xacro:inertial_sphere>
    </link>
    <gazebo reference="caster_wheel">
        <material>Gazebo/Black</material>
        <mu1 value="0.001"/>
        <mu2 value="0.001"/>
    </gazebo>

    <!-- REAR LEFT CASTER WHEEL LINK -->

    <joint name="rear_left_caster_wheel_joint" type="continuous">
        <parent link="chassis"/>
        <child link="rear_left_caster_wheel"/>
        <origin xyz="-0.03 0.1 0"/>
    </joint>

    <link name="rear_left_caster_wheel">
        <visual>
            <geometry>
                <sphere radius="0.05"/>
            </geometry>
            <material name="black"/>
        </visual>
        <collision>
            <geometry>
                <sphere radius="0.05"/>
            </geometry>
        </collision>
        <xacro:inertial_sphere mass="0.1" radius="0.05">
            <origin xyz="0 0 0" rpy="0 0 0"/>
        </xacro:inertial_sphere>
    </link>
    <gazebo reference="caster_wheel">
        <material>Gazebo/Black</material>
        <mu1 value="0.001"/>
        <mu2 value="0.001"/>
    </gazebo>

    <!-- REAR RIGHT CASTER WHEEL LINK -->

    <joint name="rear_right_caster_wheel_joint" type="continuous">
        <parent link="chassis"/>
        <child link="rear_right_caster_wheel"/>
        <origin xyz="-0.03 -0.1 0"/>
    </joint>

    <link name="rear_right_caster_wheel">
        <visual>
            <geometry>
                <sphere radius="0.05"/>
            </geometry>
            <material name="black"/>
        </visual>
        <collision>
            <geometry>
                <sphere radius="0.05"/>
            </geometry>
        </collision>
        <xacro:inertial_sphere mass="0.1" radius="0.05">
            <origin xyz="0 0 0" rpy="0 0 0"/>
        </xacro:inertial_sphere>
    </link>
    <gazebo reference="caster_wheel">
        <material>Gazebo/Black</material>
        <mu1 value="0.001"/>
        <mu2 value="0.001"/>
    </gazebo>
    
    <!-- FRONT SONAR --> 
    <joint name="sonar_front_joint" type="fixed">
        <axis xyz="0 1 0" />
        <origin rpy="0 0 0" xyz="0.54 0 0" />
        <parent link="body_base"/>
        <child link="base_sonar_front"/>
    </joint>
    <link name="base_sonar_front">
        <collision>
        <origin xyz="0 0 0" rpy="0 0 0"/>
        <geometry>
            <box size="0.01 0.01 0.01"/>
        </geometry>
        </collision>
        <visual>
        <origin xyz="0 0 0" rpy="0 0 0"/>
        <geometry>
            <box size="0.01 0.01 0.01"/>
        </geometry>
        </visual>
        <inertial>
        <mass value="1e-5" />
        <origin xyz="0 0 0" rpy="0 0 0"/>
        <inertia ixx="1e-6" ixy="0" ixz="0" iyy="1e-6" iyz="0" izz="1e-6" />
        </inertial>
    </link>
    <gazebo reference="base_sonar_front">        
        <sensor type="ray" name="TeraRanger">
            <pose>0 0 0 0 0 0</pose>
            <visualize>true</visualize>
            <update_rate>50</update_rate>
            <ray>
                <scan>
                    <horizontal>
                    <samples>10</samples>
                    <resolution>1</resolution> 
                    <min_angle>-0.14835</min_angle>
                    <max_angle>0.14835</max_angle>
                    </horizontal>
                    <vertical>
                    <samples>10</samples>
                    <resolution>1</resolution> 
                    <min_angle>-0.14835</min_angle>
                    <max_angle>0.14835</max_angle> 
                    </vertical>
                </scan>
                <range>
                    <min>0.01</min>
                    <max>2</max>
                    <resolution>0.02</resolution>
                </range>
            </ray>
            <plugin filename="libgazebo_ros_range.so" name="gazebo_ros_range">
                <gaussianNoise>0.005</gaussianNoise>
                <alwaysOn>true</alwaysOn>
                <updateRate>50</updateRate>
                <topicName>sensor/sonar_front</topicName>
                <frameName>base_sonar_front</frameName>
                <radiation>INFRARED</radiation>
                <fov>0.2967</fov>
            </plugin>
        </sensor>  
    </gazebo>

<!-- REAR SONAR --> 
    <joint name="sonar_rear_joint" type="fixed">
        <axis xyz="0 1 0" />
        <origin rpy="0 0 3.1415" xyz="-0.04 0 0" />
        <parent link="body_base"/>
        <child link="base_sonar_rear"/>
    </joint>
    <link name="base_sonar_rear">
        <collision>
        <origin xyz="0 0 0" rpy="0 0 0"/>
        <geometry>
            <box size="0.01 0.01 0.01"/>
        </geometry>
        </collision>
        <visual>
        <origin xyz="0 0 0" rpy="0 0 0"/>
        <geometry>
            <box size="0.01 0.01 0.01"/>
        </geometry>
        </visual>
        <inertial>
        <mass value="1e-5" />
        <origin xyz="0 0 0" rpy="0 0 0"/>
        <inertia ixx="1e-6" ixy="0" ixz="0" iyy="1e-6" iyz="0" izz="1e-6" />
        </inertial>
    </link>
    <gazebo reference="base_sonar_rear">        
        <sensor type="ray" name="TeraRanger">
            <pose>0 0 0 0 0 0</pose>
            <visualize>true</visualize>
            <update_rate>50</update_rate>
            <ray>
                <scan>
                    <horizontal>
                    <samples>10</samples>
                    <resolution>1</resolution> 
                    <min_angle>-0.14835</min_angle>
                    <max_angle>0.14835</max_angle>
                    </horizontal>
                    <vertical>
                    <samples>10</samples>
                    <resolution>1</resolution> 
                    <min_angle>-0.14835</min_angle>
                    <max_angle>0.14835</max_angle> 
                    </vertical>
                </scan>
                <range>
                    <min>0.01</min>
                    <max>2</max>
                    <resolution>0.02</resolution>
                </range>
            </ray>
            <plugin filename="libgazebo_ros_range.so" name="gazebo_ros_range">
                <gaussianNoise>0.005</gaussianNoise>
                <alwaysOn>true</alwaysOn>
                <updateRate>50</updateRate>
                <topicName>sensor/sonar_rear</topicName>
                <frameName>base_sonar_rear</frameName>
                <radiation>INFRARED</radiation>
                <fov>0.2967</fov>
            </plugin>
        </sensor>  
    </gazebo>

<!-- LEFT SONAR --> 
    <joint name="sonar_left_joint" type="fixed">
        <axis xyz="0 1 0" />
        <origin rpy="0 0 1.57" xyz="0.25 0.29 0" />
        <parent link="body_base"/>
        <child link="base_sonar_left"/>
    </joint>
    <link name="base_sonar_left">
        <collision>
        <origin xyz="0 0 0" rpy="0 0 0"/>
        <geometry>
            <box size="0.01 0.01 0.01"/>
        </geometry>
        </collision>
        <visual>
        <origin xyz="0 0 0" rpy="0 0 0"/>
        <geometry>
            <box size="0.01 0.01 0.01"/>
        </geometry>
        </visual>
        <inertial>
        <mass value="1e-5" />
        <origin xyz="0 0 0" rpy="0 0 0"/>
        <inertia ixx="1e-6" ixy="0" ixz="0" iyy="1e-6" iyz="0" izz="1e-6" />
        </inertial>
    </link>
    <gazebo reference="base_sonar_left">        
        <sensor type="ray" name="TeraRanger">
            <pose>0 0 0 0 0 0</pose>
            <visualize>true</visualize>
            <update_rate>50</update_rate>
            <ray>
                <scan>
                    <horizontal>
                    <samples>10</samples>
                    <resolution>1</resolution> 
                    <min_angle>-0.14835</min_angle>
                    <max_angle>0.14835</max_angle>
                    </horizontal>
                    <vertical>
                    <samples>10</samples>
                    <resolution>1</resolution> 
                    <min_angle>-0.14835</min_angle>
                    <max_angle>0.14835</max_angle> 
                    </vertical>
                </scan>
                <range>
                    <min>0.01</min>
                    <max>2</max>
                    <resolution>0.02</resolution>
                </range>
            </ray>
            <plugin filename="libgazebo_ros_range.so" name="gazebo_ros_range">
                <gaussianNoise>0.005</gaussianNoise>
                <alwaysOn>true</alwaysOn>
                <updateRate>50</updateRate>
                <topicName>sensor/sonar_left</topicName>
                <frameName>base_sonar_left</frameName>
                <radiation>INFRARED</radiation>
                <fov>0.2967</fov>
            </plugin>
        </sensor>  
    </gazebo>

<!-- RIGHT SONAR --> 
    <joint name="sonar_right_joint" type="fixed">
        <axis xyz="0 1 0" />
        <origin rpy="0 0 -1.57" xyz="0.25 -0.29 0" />
        <parent link="body_base"/>
        <child link="base_sonar_right"/>
    </joint>
    <link name="base_sonar_right">
        <collision>
        <origin xyz="0 0 0" rpy="0 0 0"/>
        <geometry>
            <box size="0.01 0.01 0.01"/>
        </geometry>
        </collision>
        <visual>
        <origin xyz="0 0 0" rpy="0 0 0"/>
        <geometry>
            <box size="0.01 0.01 0.01"/>
        </geometry>
        </visual>
        <inertial>
        <mass value="1e-5" />
        <origin xyz="0 0 0" rpy="0 0 0"/>
        <inertia ixx="1e-6" ixy="0" ixz="0" iyy="1e-6" iyz="0" izz="1e-6" />
        </inertial>
    </link>
    <gazebo reference="base_sonar_right">        
        <sensor type="ray" name="TeraRanger">
            <pose>0 0 0 0 0 0</pose>
            <visualize>true</visualize>
            <update_rate>50</update_rate>
            <ray>
                <scan>
                    <horizontal>
                    <samples>10</samples>
                    <resolution>1</resolution> 
                    <min_angle>-0.14835</min_angle>
                    <max_angle>0.14835</max_angle>
                    </horizontal>
                    <vertical>
                    <samples>10</samples>
                    <resolution>1</resolution> 
                    <min_angle>-0.14835</min_angle>
                    <max_angle>0.14835</max_angle> 
                    </vertical>
                </scan>
                <range>
                    <min>0.01</min>
                    <max>2</max>
                    <resolution>0.02</resolution>
                </range>
            </ray>
            <plugin filename="libgazebo_ros_range.so" name="gazebo_ros_range">
                <gaussianNoise>0.005</gaussianNoise>
                <alwaysOn>true</alwaysOn>
                <updateRate>50</updateRate>
                <topicName>sensor/sonar_right</topicName>
                <frameName>base_sonar_right</frameName>
                <radiation>INFRARED</radiation>
                <fov>0.2967</fov>
            </plugin>
        </sensor>  
    </gazebo>
</robot>